Workbook

Sheet Dane wejściowe
A1: 🚗 AdRide — Unit Economics Calculator
A2: Zmień żółte komórki (lub użyj suwaków) — wyniki aktualizują się automatycznie we wszystkich arkuszach
A3: 🚘 FLOTA & EKSPOZYCJA
A4: Parametr | B4: Wartość | C4: Uwagi | D4: ↕
A5: Liczba aut | B5: 10 | C5: aut (1–100) | D5: ↕
A6: Kilometry / auto / mies. | B6: =F6*100 | C6: km — rzeczywista ekspozycja GPS | D6: ↕ | F6: 10
A7: % km pozamiejskich | B7: =F7*5 | C7: % km drogi/jazda >50 km/h (taniej, mniej ekspozycji) | D7: ↕ | F7: 6
A8: Wartość auta | B8: =F8*10000 | C8: zł — referencja: 200 000 zł | D8: ↕ | F8: 20
A9: Czas kampanii | B9: 6 | C9: miesięcy | D9: ↕
A10: 👤 KIEROWCA (stawki miejska / pozamiejska)
A11: Parametr | B11: Wartość | C11: Uwagi | D11: ↕
A12: Stawka kierowcy / km miejski | B12: =F12*0.05 | C12: zł/km — teren zabud. ≤50 km/h | D12: ↕ | F12: 12
A13: Stawka kierowcy / km pozamiejski | B13: =F13*0.05 | C13: zł/km — drogi/jazda >50 km/h | D13: ↕ | F13: 5
A14: Współczynnik oklejenia | B14: 1 | C14: 1.0=całe, 0.5=pół, 0.3=naklejki
A15: 📦 MODEL — ABONAMENTOWY (AdRide org. oklejenie, min. 12 mc)
A16: Parametr | B16: Wartość | C16: Uwagi | D16: ↕
A17: Koszt oklejenia / auto | B17: =F17*500 | C17: zł netto | D17: ↕ | F17: 16
A18: Koszt demontażu / auto | B18: =F18*100 | C18: zł netto | D18: ↕ | F18: 12
A19: Narzut ABO vs SUB (%) | B19: =F19*5 | C19: % — kryje oklejenie + logistykę (ABO droższy) | D19: ↕ | F19: 17
A20: 💰 PRICING (per-km, miejska / pozamiejska)
A21: Parametr | B21: Wartość | C21: Uwagi | D21: ↕
A22: Stawka reklamodawcy / km miejski | B22: =F22*0.1 | C22: zł/km — teren zabud. ≤50 km/h | D22: ↕ | F22: 12
A23: Stawka reklamodawcy / km pozamiejski | B23: =F23*0.1 | C23: zł/km — drogi/jazda >50 km/h | D23: ↕ | F23: 5
A24: Współczynnik prestiżu | B24: =F24*0.05 | C24: premium za wartość auta (symetryczny) | D24: ↕ | F24: 6
A25: Marża docelowa (%) | B25: 30 | C25: % (próg alertu) | D25: ↕
A26: 🔒 KOSZTY
A27: Parametr | B27: Wartość | C27: Uwagi | D27: ↕
A28: Jednorazowy audyt prawny | B28: =F28*1000 | C28: zł netto — koszt startu, NIE miesięczny | D28: ↕ | F28: 15
A29: Koszty ops. platformy / mies. | B29: =F29*250 | C29: zł/mies. | D29: ↕ | F29: 8

Sheet Subskrypcyjny
A1: AdRide — Subskrypcyjny
A2: ◆ Subskrypcyjny — Reklamodawca organizuje oklejenie. AdRide pobiera fee platformy.
A4: 📐 Formuły składowe (/ auto / mies.)
A5: Parametr | B5: Formuła / opis | C5: Wartość
A6: Współczynnik wartości auta | C6: =('Dane wejściowe'!B8/200000)
A7: Współczynnik prestiżu (symetr.) | C7: =(1+(('Dane wejściowe'!B8/200000)-1)*'Dane wejściowe'!B24)
A8: Ekspozycja: km / auto / mies. | C8: ='Dane wejściowe'!B6
A9: Stawka kier. mieszana / km | C9: =('Dane wejściowe'!B12*(1-('Dane wejściowe'!B7/100))+'Dane wejściowe'!B13*('Dane wejściowe'!B7/100))
A10: Stawka rekl. mieszana / km | C10: =('Dane wejściowe'!B22*(1-('Dane wejściowe'!B7/100))+'Dane wejściowe'!B23*('Dane wejściowe'!B7/100))
A11: Wypłata kierowcy / auto / mies. | C11: ='Dane wejściowe'!B6*('Dane wejściowe'!B12*(1-('Dane wejściowe'!B7/100))+'Dane wejściowe'!B13*('Dane wejściowe'!B7/100))*(1+(('Dane wejściowe'!B8/200000)-1)*'Dane wejściowe'!B24)*'Dane wejściowe'!B14
A12: Przychód AdRide / auto / mies. | C12: ='Dane wejściowe'!B6*('Dane wejściowe'!B22*(1-('Dane wejściowe'!B7/100))+'Dane wejściowe'!B23*('Dane wejściowe'!B7/100))*(1+(('Dane wejściowe'!B8/200000)-1)*'Dane wejściowe'!B24)
A13: Koszt zmienny / auto / mies. | C13: ='Dane wejściowe'!B6*('Dane wejściowe'!B12*(1-('Dane wejściowe'!B7/100))+'Dane wejściowe'!B13*('Dane wejściowe'!B7/100))*(1+(('Dane wejściowe'!B8/200000)-1)*'Dane wejściowe'!B24)*'Dane wejściowe'!B14
A14: Marża brutto / auto / mies. | C14: =('Dane wejściowe'!B6*('Dane wejściowe'!B22*(1-('Dane wejściowe'!B7/100))+'Dane wejściowe'!B23*('Dane wejściowe'!B7/100))*(1+(('Dane wejściowe'!B8/200000)-1)*'Dane wejściowe'!B24))-('Dane wejściowe'!B6*('Dane wejściowe'!B12*(1-('Dane wejściowe'!B7/100))+'Dane wejściowe'!B13*('Dane wejściowe'!B7/100))*(1+(('Dane wejściowe'!B8/200000)-1)*'Dane wejściowe'!B24)*'Dane wejściowe'!B14)
A15: Marża brutto % | C15: =IFERROR((('Dane wejściowe'!B6*('Dane wejściowe'!B22*(1-('Dane wejściowe'!B7/100))+'Dane wejściowe'!B23*('Dane wejściowe'!B7/100))*(1+(('Dane wejściowe'!B8/200000)-1)*'Dane wejściowe'!B24))-('Dane wejściowe'!B6*('Dane wejściowe'!B12*(1-('Dane wejściowe'!B7/100))+'Dane wejściowe'!B13*('Dane wejściowe'!B7/100))*(1+(('Dane wejściowe'!B8/200000)-1)*'Dane wejściowe'!B24)*'Dane wejściowe'!B14))/('Dane wejściowe'!B6*('Dane wejściowe'!B22*(1-('Dane wejściowe'!B7/100))+'Dane wejściowe'!B23*('Dane wejściowe'!B7/100))*(1+(('Dane wejściowe'!B8/200000)-1)*'Dane wejściowe'!B24))*100,0)
A17: 💧 Waterfall P&L platformy / mies. (audyt prawny = koszt jednorazowy, poza P&L)
A18: Pozycja | B18: Opis | C18: Kwota (zł/mies.) | D18: % przychodów
A19: 📈 Przychód (fee platformy) | B19: ='Dane wejściowe'!B5 aut × rev/auto | C19: =(('Dane wejściowe'!B6*('Dane wejściowe'!B22*(1-('Dane wejściowe'!B7/100))+'Dane wejściowe'!B23*('Dane wejściowe'!B7/100))*(1+(('Dane wejściowe'!B8/200000)-1)*'Dane wejściowe'!B24))*'Dane wejściowe'!B5) | D19: =IFERROR((('Dane wejściowe'!B6*('Dane wejściowe'!B22*(1-('Dane wejściowe'!B7/100))+'Dane wejściowe'!B23*('Dane wejściowe'!B7/100))*(1+(('Dane wejściowe'!B8/200000)-1)*'Dane wejściowe'!B24))*'Dane wejściowe'!B5)/((('Dane wejściowe'!B6*('Dane wejściowe'!B22*(1-('Dane wejściowe'!B7/100))+'Dane wejściowe'!B23*('Dane wejściowe'!B7/100))*(1+(('Dane wejściowe'!B8/200000)-1)*'Dane wejściowe'!B24))*'Dane wejściowe'!B5))*100,0)
A20: 📉 Wypłata kierowców | B20: ='Dane wejściowe'!B5 aut × payout/auto | C20: =-('Dane wejściowe'!B6*('Dane wejściowe'!B12*(1-('Dane wejściowe'!B7/100))+'Dane wejściowe'!B13*('Dane wejściowe'!B7/100))*(1+(('Dane wejściowe'!B8/200000)-1)*'Dane wejściowe'!B24)*'Dane wejściowe'!B14)*'Dane wejściowe'!B5 | D20: =IFERROR(-('Dane wejściowe'!B6*('Dane wejściowe'!B12*(1-('Dane wejściowe'!B7/100))+'Dane wejściowe'!B13*('Dane wejściowe'!B7/100))*(1+(('Dane wejściowe'!B8/200000)-1)*'Dane wejściowe'!B24)*'Dane wejściowe'!B14)*'Dane wejściowe'!B5/((('Dane wejściowe'!B6*('Dane wejściowe'!B22*(1-('Dane wejściowe'!B7/100))+'Dane wejściowe'!B23*('Dane wejściowe'!B7/100))*(1+(('Dane wejściowe'!B8/200000)-1)*'Dane wejściowe'!B24))*'Dane wejściowe'!B5))*100,0)
A21: 📉 Koszty ops. platformy | B21: stały / mies. | C21: =-'Dane wejściowe'!B29 | D21: =IFERROR(-'Dane wejściowe'!B29/((('Dane wejściowe'!B6*('Dane wejściowe'!B22*(1-('Dane wejściowe'!B7/100))+'Dane wejściowe'!B23*('Dane wejściowe'!B7/100))*(1+(('Dane wejściowe'!B8/200000)-1)*'Dane wejściowe'!B24))*'Dane wejściowe'!B5))*100,0)
A22: ✅ ZYSK OPERACYJNY / mies. | B22: bez kosztu prawnego (jednorazowy) | C22: =(('Dane wejściowe'!B6*('Dane wejściowe'!B22*(1-('Dane wejściowe'!B7/100))+'Dane wejściowe'!B23*('Dane wejściowe'!B7/100))*(1+(('Dane wejściowe'!B8/200000)-1)*'Dane wejściowe'!B24))*'Dane wejściowe'!B5)-(('Dane wejściowe'!B6*('Dane wejściowe'!B12*(1-('Dane wejściowe'!B7/100))+'Dane wejściowe'!B13*('Dane wejściowe'!B7/100))*(1+(('Dane wejściowe'!B8/200000)-1)*'Dane wejściowe'!B24)*'Dane wejściowe'!B14)*'Dane wejściowe'!B5)-'Dane wejściowe'!B29 | D22: =IFERROR(((('Dane wejściowe'!B6*('Dane wejściowe'!B22*(1-('Dane wejściowe'!B7/100))+'Dane wejściowe'!B23*('Dane wejściowe'!B7/100))*(1+(('Dane wejściowe'!B8/200000)-1)*'Dane wejściowe'!B24))*'Dane wejściowe'!B5)-(('Dane wejściowe'!B6*('Dane wejściowe'!B12*(1-('Dane wejściowe'!B7/100))+'Dane wejściowe'!B13*('Dane wejściowe'!B7/100))*(1+(('Dane wejściowe'!B8/200000)-1)*'Dane wejściowe'!B24)*'Dane wejściowe'!B14)*'Dane wejściowe'!B5)-'Dane wejściowe'!B29)/((('Dane wejściowe'!B6*('Dane wejściowe'!B22*(1-('Dane wejściowe'!B7/100))+'Dane wejściowe'!B23*('Dane wejściowe'!B7/100))*(1+(('Dane wejściowe'!B8/200000)-1)*'Dane wejściowe'!B24))*'Dane wejściowe'!B5))*100,0)
A24: 🎯 Jednorazowy koszt startu i Break-Even
A25: Metryka | B25: Wartość | C25: Interpretacja
A26: Jednorazowy audyt prawny | B26: ='Dane wejściowe'!B28 | C26: Koszt poniesiony RAZ przy starcie — niezależny od liczby umów
A27: Zysk operacyjny / mies. | B27: =((('Dane wejściowe'!B6*('Dane wejściowe'!B22*(1-('Dane wejściowe'!B7/100))+'Dane wejściowe'!B23*('Dane wejściowe'!B7/100))*(1+(('Dane wejściowe'!B8/200000)-1)*'Dane wejściowe'!B24))*'Dane wejściowe'!B5)-(('Dane wejściowe'!B6*('Dane wejściowe'!B12*(1-('Dane wejściowe'!B7/100))+'Dane wejściowe'!B13*('Dane wejściowe'!B7/100))*(1+(('Dane wejściowe'!B8/200000)-1)*'Dane wejściowe'!B24)*'Dane wejściowe'!B14)*'Dane wejściowe'!B5)-'Dane wejściowe'!B29) | C27: Miesięczna nadwyżka do spłaty startu
A28: Miesięcy do zwrotu audytu | B28: =IFERROR(IF(((('Dane wejściowe'!B6*('Dane wejściowe'!B22*(1-('Dane wejściowe'!B7/100))+'Dane wejściowe'!B23*('Dane wejściowe'!B7/100))*(1+(('Dane wejściowe'!B8/200000)-1)*'Dane wejściowe'!B24))*'Dane wejściowe'!B5)-(('Dane wejściowe'!B6*('Dane wejściowe'!B12*(1-('Dane wejściowe'!B7/100))+'Dane wejściowe'!B13*('Dane wejściowe'!B7/100))*(1+(('Dane wejściowe'!B8/200000)-1)*'Dane wejściowe'!B24)*'Dane wejściowe'!B14)*'Dane wejściowe'!B5)-'Dane wejściowe'!B29)>0,'Dane wejściowe'!B28/((('Dane wejściowe'!B6*('Dane wejściowe'!B22*(1-('Dane wejściowe'!B7/100))+'Dane wejściowe'!B23*('Dane wejściowe'!B7/100))*(1+(('Dane wejściowe'!B8/200000)-1)*'Dane wejściowe'!B24))*'Dane wejściowe'!B5)-(('Dane wejściowe'!B6*('Dane wejściowe'!B12*(1-('Dane wejściowe'!B7/100))+'Dane wejściowe'!B13*('Dane wejściowe'!B7/100))*(1+(('Dane wejściowe'!B8/200000)-1)*'Dane wejściowe'!B24)*'Dane wejściowe'!B14)*'Dane wejściowe'!B5)-'Dane wejściowe'!B29),"N/A"),"N/A") | C28: =audyt prawny ÷ zysk operacyjny / mies. (przy 'Dane wejściowe'!B5 autach)
A29: Pokrycie kosztów stałych | B29: =IFERROR('Dane wejściowe'!B29/(('Dane wejściowe'!B6*('Dane wejściowe'!B22*(1-('Dane wejściowe'!B7/100))+'Dane wejściowe'!B23*('Dane wejściowe'!B7/100))*(1+(('Dane wejściowe'!B8/200000)-1)*'Dane wejściowe'!B24))*'Dane wejściowe'!B5)-(('Dane wejściowe'!B6*('Dane wejściowe'!B12*(1-('Dane wejściowe'!B7/100))+'Dane wejściowe'!B13*('Dane wejściowe'!B7/100))*(1+(('Dane wejściowe'!B8/200000)-1)*'Dane wejściowe'!B24)*'Dane wejściowe'!B14)*'Dane wejściowe'!B5),"N/A") | C29: % zysku brutto zajęty przez ops (< 1 = opłacalne operacyjnie)
A31: 💼 Całkowity koszt reklamodawcy (za kampanię)
A32: Składnik | B32: Wzór | C32: Łącznie | D32: / auto | E32: / auto / mies.
A33: Opłata platformy AdRide | B33: rev/auto × N × months | C33: =('Dane wejściowe'!B6*('Dane wejściowe'!B22*(1-('Dane wejściowe'!B7/100))+'Dane wejściowe'!B23*('Dane wejściowe'!B7/100))*(1+(('Dane wejściowe'!B8/200000)-1)*'Dane wejściowe'!B24))*'Dane wejściowe'!B5*'Dane wejściowe'!B9 | D33: =('Dane wejściowe'!B6*('Dane wejściowe'!B22*(1-('Dane wejściowe'!B7/100))+'Dane wejściowe'!B23*('Dane wejściowe'!B7/100))*(1+(('Dane wejściowe'!B8/200000)-1)*'Dane wejściowe'!B24))*'Dane wejściowe'!B9 | E33: ='Dane wejściowe'!B6*('Dane wejściowe'!B22*(1-('Dane wejściowe'!B7/100))+'Dane wejściowe'!B23*('Dane wejściowe'!B7/100))*(1+(('Dane wejściowe'!B8/200000)-1)*'Dane wejściowe'!B24)
A34: Koszt oklejenia + demontażu (reklamodawca płaci sam) | B34: (wrapCost+unwrapCost)×N — poza AdRide | C34: =('Dane wejściowe'!B17+'Dane wejściowe'!B18)*'Dane wejściowe'!B5 | D34: ='Dane wejściowe'!B17+'Dane wejściowe'!B18 | E34: =('Dane wejściowe'!B17+'Dane wejściowe'!B18)/'Dane wejściowe'!B9 | F34: ⚠ Poza platformą
A35: 💰 ŁĄCZNY KOSZT REKLAMODAWCY | C35: =(('Dane wejściowe'!B6*('Dane wejściowe'!B22*(1-('Dane wejściowe'!B7/100))+'Dane wejściowe'!B23*('Dane wejściowe'!B7/100))*(1+(('Dane wejściowe'!B8/200000)-1)*'Dane wejściowe'!B24))*'Dane wejściowe'!B5*'Dane wejściowe'!B9)+(('Dane wejściowe'!B17+'Dane wejściowe'!B18)*'Dane wejściowe'!B5) | D35: =((('Dane wejściowe'!B6*('Dane wejściowe'!B22*(1-('Dane wejściowe'!B7/100))+'Dane wejściowe'!B23*('Dane wejściowe'!B7/100))*(1+(('Dane wejściowe'!B8/200000)-1)*'Dane wejściowe'!B24))*'Dane wejściowe'!B5*'Dane wejściowe'!B9)+(('Dane wejściowe'!B17+'Dane wejściowe'!B18)*'Dane wejściowe'!B5))/'Dane wejściowe'!B5 | E35: =((('Dane wejściowe'!B6*('Dane wejściowe'!B22*(1-('Dane wejściowe'!B7/100))+'Dane wejściowe'!B23*('Dane wejściowe'!B7/100))*(1+(('Dane wejściowe'!B8/200000)-1)*'Dane wejściowe'!B24))*'Dane wejściowe'!B5*'Dane wejściowe'!B9)+(('Dane wejściowe'!B17+'Dane wejściowe'!B18)*'Dane wejściowe'!B5))/('Dane wejściowe'!B5*'Dane wejściowe'!B9)
A37: 🔍 P&L na jedno auto / mies.
A38: Pozycja | B38: Kwota / auto
A39: Przychód (fee platformy) | B39: ='Dane wejściowe'!B6*('Dane wejściowe'!B22*(1-('Dane wejściowe'!B7/100))+'Dane wejściowe'!B23*('Dane wejściowe'!B7/100))*(1+(('Dane wejściowe'!B8/200000)-1)*'Dane wejściowe'!B24)
A40: Wypłata kierowcy | B40: =-('Dane wejściowe'!B6*('Dane wejściowe'!B12*(1-('Dane wejściowe'!B7/100))+'Dane wejściowe'!B13*('Dane wejściowe'!B7/100))*(1+(('Dane wejściowe'!B8/200000)-1)*'Dane wejściowe'!B24)*'Dane wejściowe'!B14)
A41: Marża brutto | B41: =('Dane wejściowe'!B6*('Dane wejściowe'!B22*(1-('Dane wejściowe'!B7/100))+'Dane wejściowe'!B23*('Dane wejściowe'!B7/100))*(1+(('Dane wejściowe'!B8/200000)-1)*'Dane wejściowe'!B24))-('Dane wejściowe'!B6*('Dane wejściowe'!B12*(1-('Dane wejściowe'!B7/100))+'Dane wejściowe'!B13*('Dane wejściowe'!B7/100))*(1+(('Dane wejściowe'!B8/200000)-1)*'Dane wejściowe'!B24)*'Dane wejściowe'!B14)
A42: Ops. platforma / auto | B42: =-'Dane wejściowe'!B29/'Dane wejściowe'!B5
A43: Marża operacyjna netto / auto | B43: =((('Dane wejściowe'!B6*('Dane wejściowe'!B22*(1-('Dane wejściowe'!B7/100))+'Dane wejściowe'!B23*('Dane wejściowe'!B7/100))*(1+(('Dane wejściowe'!B8/200000)-1)*'Dane wejściowe'!B24))*'Dane wejściowe'!B5)-(('Dane wejściowe'!B6*('Dane wejściowe'!B12*(1-('Dane wejściowe'!B7/100))+'Dane wejściowe'!B13*('Dane wejściowe'!B7/100))*(1+(('Dane wejściowe'!B8/200000)-1)*'Dane wejściowe'!B24)*'Dane wejściowe'!B14)*'Dane wejściowe'!B5)-'Dane wejściowe'!B29)/'Dane wejściowe'!B5

Sheet Abonamentowy
A1: AdRide — Abonamentowy
A2: ✦ Abonamentowy — AdRide organizuje oklejenie. Koszt absorbowany w marży.
A4: 📐 Formuły składowe (/ auto / mies.)
A5: Parametr | B5: Formuła / opis | C5: Wartość
A6: Współczynnik wartości auta | C6: =('Dane wejściowe'!B8/200000)
A7: Współczynnik prestiżu (symetr.) | C7: =(1+(('Dane wejściowe'!B8/200000)-1)*'Dane wejściowe'!B24)
A8: Ekspozycja: km / auto / mies. | C8: ='Dane wejściowe'!B6
A9: Stawka kier. mieszana / km | C9: =('Dane wejściowe'!B12*(1-('Dane wejściowe'!B7/100))+'Dane wejściowe'!B13*('Dane wejściowe'!B7/100))
A10: Stawka rekl. mieszana / km | C10: =('Dane wejściowe'!B22*(1-('Dane wejściowe'!B7/100))+'Dane wejściowe'!B23*('Dane wejściowe'!B7/100))
A11: Wypłata kierowcy / auto / mies. | C11: ='Dane wejściowe'!B6*('Dane wejściowe'!B12*(1-('Dane wejściowe'!B7/100))+'Dane wejściowe'!B13*('Dane wejściowe'!B7/100))*(1+(('Dane wejściowe'!B8/200000)-1)*'Dane wejściowe'!B24)*'Dane wejściowe'!B14
A12: Przychód AdRide / auto / mies. | C12: ='Dane wejściowe'!B6*('Dane wejściowe'!B22*(1-('Dane wejściowe'!B7/100))+'Dane wejściowe'!B23*('Dane wejściowe'!B7/100))*(1+(('Dane wejściowe'!B8/200000)-1)*'Dane wejściowe'!B24)*(1+'Dane wejściowe'!B19/100)
A13: Amortyzacja oklejenia / auto / mies. | C13: ='Dane wejściowe'!B17/MAX('Dane wejściowe'!B9,12)
A14: Amortyzacja demontażu / auto / mies. | C14: ='Dane wejściowe'!B18/MAX('Dane wejściowe'!B9,12)
A15: Koszt zmienny / auto / mies. | C15: ='Dane wejściowe'!B6*('Dane wejściowe'!B12*(1-('Dane wejściowe'!B7/100))+'Dane wejściowe'!B13*('Dane wejściowe'!B7/100))*(1+(('Dane wejściowe'!B8/200000)-1)*'Dane wejściowe'!B24)*'Dane wejściowe'!B14+'Dane wejściowe'!B17/MAX('Dane wejściowe'!B9,12)+'Dane wejściowe'!B18/MAX('Dane wejściowe'!B9,12)
A16: Marża brutto / auto / mies. | C16: =('Dane wejściowe'!B6*('Dane wejściowe'!B22*(1-('Dane wejściowe'!B7/100))+'Dane wejściowe'!B23*('Dane wejściowe'!B7/100))*(1+(('Dane wejściowe'!B8/200000)-1)*'Dane wejściowe'!B24)*(1+'Dane wejściowe'!B19/100))-('Dane wejściowe'!B6*('Dane wejściowe'!B12*(1-('Dane wejściowe'!B7/100))+'Dane wejściowe'!B13*('Dane wejściowe'!B7/100))*(1+(('Dane wejściowe'!B8/200000)-1)*'Dane wejściowe'!B24)*'Dane wejściowe'!B14+'Dane wejściowe'!B17/MAX('Dane wejściowe'!B9,12)+'Dane wejściowe'!B18/MAX('Dane wejściowe'!B9,12))
A17: Marża brutto % | C17: =IFERROR((('Dane wejściowe'!B6*('Dane wejściowe'!B22*(1-('Dane wejściowe'!B7/100))+'Dane wejściowe'!B23*('Dane wejściowe'!B7/100))*(1+(('Dane wejściowe'!B8/200000)-1)*'Dane wejściowe'!B24)*(1+'Dane wejściowe'!B19/100))-('Dane wejściowe'!B6*('Dane wejściowe'!B12*(1-('Dane wejściowe'!B7/100))+'Dane wejściowe'!B13*('Dane wejściowe'!B7/100))*(1+(('Dane wejściowe'!B8/200000)-1)*'Dane wejściowe'!B24)*'Dane wejściowe'!B14+'Dane wejściowe'!B17/MAX('Dane wejściowe'!B9,12)+'Dane wejściowe'!B18/MAX('Dane wejściowe'!B9,12)))/('Dane wejściowe'!B6*('Dane wejściowe'!B22*(1-('Dane wejściowe'!B7/100))+'Dane wejściowe'!B23*('Dane wejściowe'!B7/100))*(1+(('Dane wejściowe'!B8/200000)-1)*'Dane wejściowe'!B24)*(1+'Dane wejściowe'!B19/100))*100,0)
A19: 💧 Waterfall P&L platformy / mies. (audyt prawny = koszt jednorazowy, poza P&L)
A20: Pozycja | B20: Opis | C20: Kwota (zł/mies.) | D20: % przychodów
A21: 📈 Przychód (fee platformy) | B21: ='Dane wejściowe'!B5 aut × rev/auto | C21: =(('Dane wejściowe'!B6*('Dane wejściowe'!B22*(1-('Dane wejściowe'!B7/100))+'Dane wejściowe'!B23*('Dane wejściowe'!B7/100))*(1+(('Dane wejściowe'!B8/200000)-1)*'Dane wejściowe'!B24)*(1+'Dane wejściowe'!B19/100))*'Dane wejściowe'!B5) | D21: =IFERROR((('Dane wejściowe'!B6*('Dane wejściowe'!B22*(1-('Dane wejściowe'!B7/100))+'Dane wejściowe'!B23*('Dane wejściowe'!B7/100))*(1+(('Dane wejściowe'!B8/200000)-1)*'Dane wejściowe'!B24)*(1+'Dane wejściowe'!B19/100))*'Dane wejściowe'!B5)/((('Dane wejściowe'!B6*('Dane wejściowe'!B22*(1-('Dane wejściowe'!B7/100))+'Dane wejściowe'!B23*('Dane wejściowe'!B7/100))*(1+(('Dane wejściowe'!B8/200000)-1)*'Dane wejściowe'!B24)*(1+'Dane wejściowe'!B19/100))*'Dane wejściowe'!B5))*100,0)
A22: 📉 Wypłata kierowców | B22: ='Dane wejściowe'!B5 aut × payout/auto | C22: =-('Dane wejściowe'!B6*('Dane wejściowe'!B12*(1-('Dane wejściowe'!B7/100))+'Dane wejściowe'!B13*('Dane wejściowe'!B7/100))*(1+(('Dane wejściowe'!B8/200000)-1)*'Dane wejściowe'!B24)*'Dane wejściowe'!B14)*'Dane wejściowe'!B5 | D22: =IFERROR(-('Dane wejściowe'!B6*('Dane wejściowe'!B12*(1-('Dane wejściowe'!B7/100))+'Dane wejściowe'!B13*('Dane wejściowe'!B7/100))*(1+(('Dane wejściowe'!B8/200000)-1)*'Dane wejściowe'!B24)*'Dane wejściowe'!B14)*'Dane wejściowe'!B5/((('Dane wejściowe'!B6*('Dane wejściowe'!B22*(1-('Dane wejściowe'!B7/100))+'Dane wejściowe'!B23*('Dane wejściowe'!B7/100))*(1+(('Dane wejściowe'!B8/200000)-1)*'Dane wejściowe'!B24)*(1+'Dane wejściowe'!B19/100))*'Dane wejściowe'!B5))*100,0)
A23: 📉 Oklejenie (amort.) | B23: ='Dane wejściowe'!B5 aut × wrapCost/months | C23: =-('Dane wejściowe'!B17/MAX('Dane wejściowe'!B9,12))*'Dane wejściowe'!B5 | D23: =IFERROR(-('Dane wejściowe'!B17/MAX('Dane wejściowe'!B9,12))*'Dane wejściowe'!B5/((('Dane wejściowe'!B6*('Dane wejściowe'!B22*(1-('Dane wejściowe'!B7/100))+'Dane wejściowe'!B23*('Dane wejściowe'!B7/100))*(1+(('Dane wejściowe'!B8/200000)-1)*'Dane wejściowe'!B24)*(1+'Dane wejściowe'!B19/100))*'Dane wejściowe'!B5))*100,0)
A24: 📉 Demontaż (amort.) | B24: ='Dane wejściowe'!B5 aut × unwrapCost/months | C24: =-('Dane wejściowe'!B18/MAX('Dane wejściowe'!B9,12))*'Dane wejściowe'!B5 | D24: =IFERROR(-('Dane wejściowe'!B18/MAX('Dane wejściowe'!B9,12))*'Dane wejściowe'!B5/((('Dane wejściowe'!B6*('Dane wejściowe'!B22*(1-('Dane wejściowe'!B7/100))+'Dane wejściowe'!B23*('Dane wejściowe'!B7/100))*(1+(('Dane wejściowe'!B8/200000)-1)*'Dane wejściowe'!B24)*(1+'Dane wejściowe'!B19/100))*'Dane wejściowe'!B5))*100,0)
A25: 📉 Koszty ops. platformy | B25: stały / mies. | C25: =-'Dane wejściowe'!B29 | D25: =IFERROR(-'Dane wejściowe'!B29/((('Dane wejściowe'!B6*('Dane wejściowe'!B22*(1-('Dane wejściowe'!B7/100))+'Dane wejściowe'!B23*('Dane wejściowe'!B7/100))*(1+(('Dane wejściowe'!B8/200000)-1)*'Dane wejściowe'!B24)*(1+'Dane wejściowe'!B19/100))*'Dane wejściowe'!B5))*100,0)
A26: ✅ ZYSK OPERACYJNY / mies. | B26: bez kosztu prawnego (jednorazowy) | C26: =(('Dane wejściowe'!B6*('Dane wejściowe'!B22*(1-('Dane wejściowe'!B7/100))+'Dane wejściowe'!B23*('Dane wejściowe'!B7/100))*(1+(('Dane wejściowe'!B8/200000)-1)*'Dane wejściowe'!B24)*(1+'Dane wejściowe'!B19/100))*'Dane wejściowe'!B5)-(('Dane wejściowe'!B6*('Dane wejściowe'!B12*(1-('Dane wejściowe'!B7/100))+'Dane wejściowe'!B13*('Dane wejściowe'!B7/100))*(1+(('Dane wejściowe'!B8/200000)-1)*'Dane wejściowe'!B24)*'Dane wejściowe'!B14+'Dane wejściowe'!B17/MAX('Dane wejściowe'!B9,12)+'Dane wejściowe'!B18/MAX('Dane wejściowe'!B9,12))*'Dane wejściowe'!B5)-'Dane wejściowe'!B29 | D26: =IFERROR(((('Dane wejściowe'!B6*('Dane wejściowe'!B22*(1-('Dane wejściowe'!B7/100))+'Dane wejściowe'!B23*('Dane wejściowe'!B7/100))*(1+(('Dane wejściowe'!B8/200000)-1)*'Dane wejściowe'!B24)*(1+'Dane wejściowe'!B19/100))*'Dane wejściowe'!B5)-(('Dane wejściowe'!B6*('Dane wejściowe'!B12*(1-('Dane wejściowe'!B7/100))+'Dane wejściowe'!B13*('Dane wejściowe'!B7/100))*(1+(('Dane wejściowe'!B8/200000)-1)*'Dane wejściowe'!B24)*'Dane wejściowe'!B14+'Dane wejściowe'!B17/MAX('Dane wejściowe'!B9,12)+'Dane wejściowe'!B18/MAX('Dane wejściowe'!B9,12))*'Dane wejściowe'!B5)-'Dane wejściowe'!B29)/((('Dane wejściowe'!B6*('Dane wejściowe'!B22*(1-('Dane wejściowe'!B7/100))+'Dane wejściowe'!B23*('Dane wejściowe'!B7/100))*(1+(('Dane wejściowe'!B8/200000)-1)*'Dane wejściowe'!B24)*(1+'Dane wejściowe'!B19/100))*'Dane wejściowe'!B5))*100,0)
A28: 🎯 Jednorazowy koszt startu i Break-Even
A29: Metryka | B29: Wartość | C29: Interpretacja
A30: Jednorazowy audyt prawny | B30: ='Dane wejściowe'!B28 | C30: Koszt poniesiony RAZ przy starcie — niezależny od liczby umów
A31: Zysk operacyjny / mies. | B31: =((('Dane wejściowe'!B6*('Dane wejściowe'!B22*(1-('Dane wejściowe'!B7/100))+'Dane wejściowe'!B23*('Dane wejściowe'!B7/100))*(1+(('Dane wejściowe'!B8/200000)-1)*'Dane wejściowe'!B24)*(1+'Dane wejściowe'!B19/100))*'Dane wejściowe'!B5)-(('Dane wejściowe'!B6*('Dane wejściowe'!B12*(1-('Dane wejściowe'!B7/100))+'Dane wejściowe'!B13*('Dane wejściowe'!B7/100))*(1+(('Dane wejściowe'!B8/200000)-1)*'Dane wejściowe'!B24)*'Dane wejściowe'!B14+'Dane wejściowe'!B17/MAX('Dane wejściowe'!B9,12)+'Dane wejściowe'!B18/MAX('Dane wejściowe'!B9,12))*'Dane wejściowe'!B5)-'Dane wejściowe'!B29) | C31: Miesięczna nadwyżka do spłaty startu
A32: Miesięcy do zwrotu audytu | B32: =IFERROR(IF(((('Dane wejściowe'!B6*('Dane wejściowe'!B22*(1-('Dane wejściowe'!B7/100))+'Dane wejściowe'!B23*('Dane wejściowe'!B7/100))*(1+(('Dane wejściowe'!B8/200000)-1)*'Dane wejściowe'!B24)*(1+'Dane wejściowe'!B19/100))*'Dane wejściowe'!B5)-(('Dane wejściowe'!B6*('Dane wejściowe'!B12*(1-('Dane wejściowe'!B7/100))+'Dane wejściowe'!B13*('Dane wejściowe'!B7/100))*(1+(('Dane wejściowe'!B8/200000)-1)*'Dane wejściowe'!B24)*'Dane wejściowe'!B14+'Dane wejściowe'!B17/MAX('Dane wejściowe'!B9,12)+'Dane wejściowe'!B18/MAX('Dane wejściowe'!B9,12))*'Dane wejściowe'!B5)-'Dane wejściowe'!B29)>0,'Dane wejściowe'!B28/((('Dane wejściowe'!B6*('Dane wejściowe'!B22*(1-('Dane wejściowe'!B7/100))+'Dane wejściowe'!B23*('Dane wejściowe'!B7/100))*(1+(('Dane wejściowe'!B8/200000)-1)*'Dane wejściowe'!B24)*(1+'Dane wejściowe'!B19/100))*'Dane wejściowe'!B5)-(('Dane wejściowe'!B6*('Dane wejściowe'!B12*(1-('Dane wejściowe'!B7/100))+'Dane wejściowe'!B13*('Dane wejściowe'!B7/100))*(1+(('Dane wejściowe'!B8/200000)-1)*'Dane wejściowe'!B24)*'Dane wejściowe'!B14+'Dane wejściowe'!B17/MAX('Dane wejściowe'!B9,12)+'Dane wejściowe'!B18/MAX('Dane wejściowe'!B9,12))*'Dane wejściowe'!B5)-'Dane wejściowe'!B29),"N/A"),"N/A") | C32: =audyt prawny ÷ zysk operacyjny / mies. (przy 'Dane wejściowe'!B5 autach)
A33: Pokrycie kosztów stałych | B33: =IFERROR('Dane wejściowe'!B29/(('Dane wejściowe'!B6*('Dane wejściowe'!B22*(1-('Dane wejściowe'!B7/100))+'Dane wejściowe'!B23*('Dane wejściowe'!B7/100))*(1+(('Dane wejściowe'!B8/200000)-1)*'Dane wejściowe'!B24)*(1+'Dane wejściowe'!B19/100))*'Dane wejściowe'!B5)-(('Dane wejściowe'!B6*('Dane wejściowe'!B12*(1-('Dane wejściowe'!B7/100))+'Dane wejściowe'!B13*('Dane wejściowe'!B7/100))*(1+(('Dane wejściowe'!B8/200000)-1)*'Dane wejściowe'!B24)*'Dane wejściowe'!B14+'Dane wejściowe'!B17/MAX('Dane wejściowe'!B9,12)+'Dane wejściowe'!B18/MAX('Dane wejściowe'!B9,12))*'Dane wejściowe'!B5),"N/A") | C33: % zysku brutto zajęty przez ops (< 1 = opłacalne operacyjnie)
A35: 💼 Całkowity koszt reklamodawcy (za kampanię)
A36: Składnik | B36: Wzór | C36: Łącznie | D36: / auto | E36: / auto / mies.
A37: Opłata platformy AdRide | B37: rev/auto × N × months | C37: =('Dane wejściowe'!B6*('Dane wejściowe'!B22*(1-('Dane wejściowe'!B7/100))+'Dane wejściowe'!B23*('Dane wejściowe'!B7/100))*(1+(('Dane wejściowe'!B8/200000)-1)*'Dane wejściowe'!B24)*(1+'Dane wejściowe'!B19/100))*'Dane wejściowe'!B5*'Dane wejściowe'!B9 | D37: =('Dane wejściowe'!B6*('Dane wejściowe'!B22*(1-('Dane wejściowe'!B7/100))+'Dane wejściowe'!B23*('Dane wejściowe'!B7/100))*(1+(('Dane wejściowe'!B8/200000)-1)*'Dane wejściowe'!B24)*(1+'Dane wejściowe'!B19/100))*'Dane wejściowe'!B9 | E37: ='Dane wejściowe'!B6*('Dane wejściowe'!B22*(1-('Dane wejściowe'!B7/100))+'Dane wejściowe'!B23*('Dane wejściowe'!B7/100))*(1+(('Dane wejściowe'!B8/200000)-1)*'Dane wejściowe'!B24)*(1+'Dane wejściowe'!B19/100)
A38: Koszt oklejenia + demontażu | B38: Absorbowany w marży AdRide | C38: 0 | D38: 0 | E38: 0 | F38: ✅ Wliczone w usługę
A39: 💰 ŁĄCZNY KOSZT REKLAMODAWCY | C39: =('Dane wejściowe'!B6*('Dane wejściowe'!B22*(1-('Dane wejściowe'!B7/100))+'Dane wejściowe'!B23*('Dane wejściowe'!B7/100))*(1+(('Dane wejściowe'!B8/200000)-1)*'Dane wejściowe'!B24)*(1+'Dane wejściowe'!B19/100))*'Dane wejściowe'!B5*'Dane wejściowe'!B9 | D39: =(('Dane wejściowe'!B6*('Dane wejściowe'!B22*(1-('Dane wejściowe'!B7/100))+'Dane wejściowe'!B23*('Dane wejściowe'!B7/100))*(1+(('Dane wejściowe'!B8/200000)-1)*'Dane wejściowe'!B24)*(1+'Dane wejściowe'!B19/100))*'Dane wejściowe'!B5*'Dane wejściowe'!B9)/'Dane wejściowe'!B5 | E39: =(('Dane wejściowe'!B6*('Dane wejściowe'!B22*(1-('Dane wejściowe'!B7/100))+'Dane wejściowe'!B23*('Dane wejściowe'!B7/100))*(1+(('Dane wejściowe'!B8/200000)-1)*'Dane wejściowe'!B24)*(1+'Dane wejściowe'!B19/100))*'Dane wejściowe'!B5*'Dane wejściowe'!B9)/('Dane wejściowe'!B5*'Dane wejściowe'!B9)
A41: 🔍 P&L na jedno auto / mies.
A42: Pozycja | B42: Kwota / auto
A43: Przychód (fee platformy) | B43: ='Dane wejściowe'!B6*('Dane wejściowe'!B22*(1-('Dane wejściowe'!B7/100))+'Dane wejściowe'!B23*('Dane wejściowe'!B7/100))*(1+(('Dane wejściowe'!B8/200000)-1)*'Dane wejściowe'!B24)*(1+'Dane wejściowe'!B19/100)
A44: Wypłata kierowcy | B44: =-('Dane wejściowe'!B6*('Dane wejściowe'!B12*(1-('Dane wejściowe'!B7/100))+'Dane wejściowe'!B13*('Dane wejściowe'!B7/100))*(1+(('Dane wejściowe'!B8/200000)-1)*'Dane wejściowe'!B24)*'Dane wejściowe'!B14)
A45: Oklejenie (amort.) | B45: =-('Dane wejściowe'!B17/MAX('Dane wejściowe'!B9,12))
...

Sheet Porównanie modeli
A1: AdRide — Porównanie: Subskrypcyjny vs Abonamentowy
A2: Metryka | B2: Subskrypcyjny (reklamodawca org. oklejenie) | C2: Abonamentowy (AdRide org. oklejenie) | D2: Uwagi
A3: PRZYCHODY ADRIDE
A4: Przychód / auto / mies. | B4: ='Dane wejściowe'!B6*('Dane wejściowe'!B22*(1-('Dane wejściowe'!B7/100))+'Dane wejściowe'!B23*('Dane wejściowe'!B7/100))*(1+(('Dane wejściowe'!B8/200000)-1)*'Dane wejściowe'!B24) | C4: ='Dane wejściowe'!B6*('Dane wejściowe'!B22*(1-('Dane wejściowe'!B7/100))+'Dane wejściowe'!B23*('Dane wejściowe'!B7/100))*(1+(('Dane wejściowe'!B8/200000)-1)*'Dane wejściowe'!B24)*(1+'Dane wejściowe'!B19/100) | D4: ABO: +narzut
A5: Przychód łącznie / mies. | B5: =('Dane wejściowe'!B6*('Dane wejściowe'!B22*(1-('Dane wejściowe'!B7/100))+'Dane wejściowe'!B23*('Dane wejściowe'!B7/100))*(1+(('Dane wejściowe'!B8/200000)-1)*'Dane wejściowe'!B24))*'Dane wejściowe'!B5 | C5: =('Dane wejściowe'!B6*('Dane wejściowe'!B22*(1-('Dane wejściowe'!B7/100))+'Dane wejściowe'!B23*('Dane wejściowe'!B7/100))*(1+(('Dane wejściowe'!B8/200000)-1)*'Dane wejściowe'!B24)*(1+'Dane wejściowe'!B19/100))*'Dane wejściowe'!B5 | D5: ABO wyższy o narzut
A6: KOSZTY ADRIDE
A7: Payout kierowcy / auto | B7: ='Dane wejściowe'!B6*('Dane wejściowe'!B12*(1-('Dane wejściowe'!B7/100))+'Dane wejściowe'!B13*('Dane wejściowe'!B7/100))*(1+(('Dane wejściowe'!B8/200000)-1)*'Dane wejściowe'!B24)*'Dane wejściowe'!B14 | C7: ='Dane wejściowe'!B6*('Dane wejściowe'!B12*(1-('Dane wejściowe'!B7/100))+'Dane wejściowe'!B13*('Dane wejściowe'!B7/100))*(1+(('Dane wejściowe'!B8/200000)-1)*'Dane wejściowe'!B24)*'Dane wejściowe'!B14 | D7: Identyczny
A8: Koszt oklejenia / auto / mies. | B8: 0 zł | C8: ='Dane wejściowe'!B17/MAX('Dane wejściowe'!B9,12) | D8: Abo: amortyzowane
A9: Koszt demontażu / auto / mies. | B9: 0 zł | C9: ='Dane wejściowe'!B18/MAX('Dane wejściowe'!B9,12) | D9: Abo: amortyzowane
A10: Koszt zmienny / auto | B10: ='Dane wejściowe'!B6*('Dane wejściowe'!B12*(1-('Dane wejściowe'!B7/100))+'Dane wejściowe'!B13*('Dane wejściowe'!B7/100))*(1+(('Dane wejściowe'!B8/200000)-1)*'Dane wejściowe'!B24)*'Dane wejściowe'!B14 | C10: ='Dane wejściowe'!B6*('Dane wejściowe'!B12*(1-('Dane wejściowe'!B7/100))+'Dane wejściowe'!B13*('Dane wejściowe'!B7/100))*(1+(('Dane wejściowe'!B8/200000)-1)*'Dane wejściowe'!B24)*'Dane wejściowe'!B14+'Dane wejściowe'!B17/MAX('Dane wejściowe'!B9,12)+'Dane wejściowe'!B18/MAX('Dane wejściowe'!B9,12) | D10: Abo wyższy
A11: MARŻE ADRIDE (miesięczne)
A12: Marża brutto / auto | B12: =('Dane wejściowe'!B6*('Dane wejściowe'!B22*(1-('Dane wejściowe'!B7/100))+'Dane wejściowe'!B23*('Dane wejściowe'!B7/100))*(1+(('Dane wejściowe'!B8/200000)-1)*'Dane wejściowe'!B24))-('Dane wejściowe'!B6*('Dane wejściowe'!B12*(1-('Dane wejściowe'!B7/100))+'Dane wejściowe'!B13*('Dane wejściowe'!B7/100))*(1+(('Dane wejściowe'!B8/200000)-1)*'Dane wejściowe'!B24)*'Dane wejściowe'!B14) | C12: =('Dane wejściowe'!B6*('Dane wejściowe'!B22*(1-('Dane wejściowe'!B7/100))+'Dane wejściowe'!B23*('Dane wejściowe'!B7/100))*(1+(('Dane wejściowe'!B8/200000)-1)*'Dane wejściowe'!B24)*(1+'Dane wejściowe'!B19/100))-('Dane wejściowe'!B6*('Dane wejściowe'!B12*(1-('Dane wejściowe'!B7/100))+'Dane wejściowe'!B13*('Dane wejściowe'!B7/100))*(1+(('Dane wejściowe'!B8/200000)-1)*'Dane wejściowe'!B24)*'Dane wejściowe'!B14+'Dane wejściowe'!B17/MAX('Dane wejściowe'!B9,12)+'Dane wejściowe'!B18/MAX('Dane wejściowe'!B9,12)) | D12: Sub wyższa o koszt oklejenia
A13: Marża brutto % | B13: =IFERROR((('Dane wejściowe'!B6*('Dane wejściowe'!B22*(1-('Dane wejściowe'!B7/100))+'Dane wejściowe'!B23*('Dane wejściowe'!B7/100))*(1+(('Dane wejściowe'!B8/200000)-1)*'Dane wejściowe'!B24))-('Dane wejściowe'!B6*('Dane wejściowe'!B12*(1-('Dane wejściowe'!B7/100))+'Dane wejściowe'!B13*('Dane wejściowe'!B7/100))*(1+(('Dane wejściowe'!B8/200000)-1)*'Dane wejściowe'!B24)*'Dane wejściowe'!B14))/('Dane wejściowe'!B6*('Dane wejściowe'!B22*(1-('Dane wejściowe'!B7/100))+'Dane wejściowe'!B23*('Dane wejściowe'!B7/100))*(1+(('Dane wejściowe'!B8/200000)-1)*'Dane wejściowe'!B24))*100,0) | C13: =IFERROR((('Dane wejściowe'!B6*('Dane wejściowe'!B22*(1-('Dane wejściowe'!B7/100))+'Dane wejściowe'!B23*('Dane wejściowe'!B7/100))*(1+(('Dane wejściowe'!B8/200000)-1)*'Dane wejściowe'!B24)*(1+'Dane wejściowe'!B19/100))-('Dane wejściowe'!B6*('Dane wejściowe'!B12*(1-('Dane wejściowe'!B7/100))+'Dane wejściowe'!B13*('Dane wejściowe'!B7/100))*(1+(('Dane wejściowe'!B8/200000)-1)*'Dane wejściowe'!B24)*'Dane wejściowe'!B14+'Dane wejściowe'!B17/MAX('Dane wejściowe'!B9,12)+'Dane wejściowe'!B18/MAX('Dane wejściowe'!B9,12)))/('Dane wejściowe'!B6*('Dane wejściowe'!B22*(1-('Dane wejściowe'!B7/100))+'Dane wejściowe'!B23*('Dane wejściowe'!B7/100))*(1+(('Dane wejściowe'!B8/200000)-1)*'Dane wejściowe'!B24)*(1+'Dane wejściowe'!B19/100))*100,0) | D13: %
A14: Zysk operacyjny / mies. | B14: =(('Dane wejściowe'!B6*('Dane wejściowe'!B22*(1-('Dane wejściowe'!B7/100))+'Dane wejściowe'!B23*('Dane wejściowe'!B7/100))*(1+(('Dane wejściowe'!B8/200000)-1)*'Dane wejściowe'!B24))*'Dane wejściowe'!B5)-(('Dane wejściowe'!B6*('Dane wejściowe'!B12*(1-('Dane wejściowe'!B7/100))+'Dane wejściowe'!B13*('Dane wejściowe'!B7/100))*(1+(('Dane wejściowe'!B8/200000)-1)*'Dane wejściowe'!B24)*'Dane wejściowe'!B14)*'Dane wejściowe'!B5)-'Dane wejściowe'!B29 | C14: =(('Dane wejściowe'!B6*('Dane wejściowe'!B22*(1-('Dane wejściowe'!B7/100))+'Dane wejściowe'!B23*('Dane wejściowe'!B7/100))*(1+(('Dane wejściowe'!B8/200000)-1)*'Dane wejściowe'!B24)*(1+'Dane wejściowe'!B19/100))*'Dane wejściowe'!B5)-(('Dane wejściowe'!B6*('Dane wejściowe'!B12*(1-('Dane wejściowe'!B7/100))+'Dane wejściowe'!B13*('Dane wejściowe'!B7/100))*(1+(('Dane wejściowe'!B8/200000)-1)*'Dane wejściowe'!B24)*'Dane wejściowe'!B14+'Dane wejściowe'!B17/MAX('Dane wejściowe'!B9,12)+'Dane wejściowe'!B18/MAX('Dane wejściowe'!B9,12))*'Dane wejściowe'!B5)-'Dane wejściowe'!B29 | D14: Bez kosztu prawnego
A15: KOSZT JEDNORAZOWY (niezależny od modelu)
A16: Audyt prawny (jednorazowo) | B16: ='Dane wejściowe'!B28 | C16: ='Dane wejściowe'!B28 | D16: Płacony raz — niezależnie od liczby klientów
A17: Mies. do zwrotu audytu | B17: =IFERROR(IF(((('Dane wejściowe'!B6*('Dane wejściowe'!B22*(1-('Dane wejściowe'!B7/100))+'Dane wejściowe'!B23*('Dane wejściowe'!B7/100))*(1+(('Dane wejściowe'!B8/200000)-1)*'Dane wejściowe'!B24))*'Dane wejściowe'!B5)-(('Dane wejściowe'!B6*('Dane wejściowe'!B12*(1-('Dane wejściowe'!B7/100))+'Dane wejściowe'!B13*('Dane wejściowe'!B7/100))*(1+(('Dane wejściowe'!B8/200000)-1)*'Dane wejściowe'!B24)*'Dane wejściowe'!B14)*'Dane wejściowe'!B5)-'Dane wejściowe'!B29)>0,'Dane wejściowe'!B28/((('Dane wejściowe'!B6*('Dane wejściowe'!B22*(1-('Dane wejściowe'!B7/100))+'Dane wejściowe'!B23*('Dane wejściowe'!B7/100))*(1+(('Dane wejściowe'!B8/200000)-1)*'Dane wejściowe'!B24))*'Dane wejściowe'!B5)-(('Dane wejściowe'!B6*('Dane wejściowe'!B12*(1-('Dane wejściowe'!B7/100))+'Dane wejściowe'!B13*('Dane wejściowe'!B7/100))*(1+(('Dane wejściowe'!B8/200000)-1)*'Dane wejściowe'!B24)*'Dane wejściowe'!B14)*'Dane wejściowe'!B5)-'Dane wejściowe'!B29),"N/A"),"N/A") | C17: =IFERROR(IF(((('Dane wejściowe'!B6*('Dane wejściowe'!B22*(1-('Dane wejściowe'!B7/100))+'Dane wejściowe'!B23*('Dane wejściowe'!B7/100))*(1+(('Dane wejściowe'!B8/200000)-1)*'Dane wejściowe'!B24)*(1+'Dane wejściowe'!B19/100))*'Dane wejściowe'!B5)-(('Dane wejściowe'!B6*('Dane wejściowe'!B12*(1-('Dane wejściowe'!B7/100))+'Dane wejściowe'!B13*('Dane wejściowe'!B7/100))*(1+(('Dane wejściowe'!B8/200000)-1)*'Dane wejściowe'!B24)*'Dane wejściowe'!B14+'Dane wejściowe'!B17/MAX('Dane wejściowe'!B9,12)+'Dane wejściowe'!B18/MAX('Dane wejściowe'!B9,12))*'Dane wejściowe'!B5)-'Dane wejściowe'!B29)>0,'Dane wejściowe'!B28/((('Dane wejściowe'!B6*('Dane wejściowe'!B22*(1-('Dane wejściowe'!B7/100))+'Dane wejściowe'!B23*('Dane wejściowe'!B7/100))*(1+(('Dane wejściowe'!B8/200000)-1)*'Dane wejściowe'!B24)*(1+'Dane wejściowe'!B19/100))*'Dane wejściowe'!B5)-(('Dane wejściowe'!B6*('Dane wejściowe'!B12*(1-('Dane wejściowe'!B7/100))+'Dane wejściowe'!B13*('Dane wejściowe'!B7/100))*(1+(('Dane wejściowe'!B8/200000)-1)*'Dane wejściowe'!B24)*'Dane wejściowe'!B14+'Dane wejściowe'!B17/MAX('Dane wejściowe'!B9,12)+'Dane wejściowe'!B18/MAX('Dane wejściowe'!B9,12))*'Dane wejściowe'!B5)-'Dane wejściowe'!B29),"N/A"),"N/A") | D17: Przy aktualnych ustawieniach
A18: KOSZTY REKLAMODAWCY
A19: Opłata AdRide (łącznie) | B19: =('Dane wejściowe'!B6*('Dane wejściowe'!B22*(1-('Dane wejściowe'!B7/100))+'Dane wejściowe'!B23*('Dane wejściowe'!B7/100))*(1+(('Dane wejściowe'!B8/200000)-1)*'Dane wejściowe'!B24))*'Dane wejściowe'!B5*'Dane wejściowe'!B9 | C19: =('Dane wejściowe'!B6*('Dane wejściowe'!B22*(1-('Dane wejściowe'!B7/100))+'Dane wejściowe'!B23*('Dane wejściowe'!B7/100))*(1+(('Dane wejściowe'!B8/200000)-1)*'Dane wejściowe'!B24)*(1+'Dane wejściowe'!B19/100))*'Dane wejściowe'!B5*'Dane wejściowe'!B9 | D19: ABO wyższy o narzut
A20: Koszt oklejenia (kto?) | B20: =('Dane wejściowe'!B17+'Dane wejściowe'!B18)*'Dane wejściowe'!B5 | C20: 0 zł (w usłudze) | D20: Sub: reklamodawca płaci
A21: ŁĄCZNY KOSZT REKLAMODAWCY | B21: =('Dane wejściowe'!B6*('Dane wejściowe'!B22*(1-('Dane wejściowe'!B7/100))+'Dane wejściowe'!B23*('Dane wejściowe'!B7/100))*(1+(('Dane wejściowe'!B8/200000)-1)*'Dane wejściowe'!B24))*'Dane wejściowe'!B5*'Dane wejściowe'!B9+('Dane wejściowe'!B17+'Dane wejściowe'!B18)*'Dane wejściowe'!B5 | C21: =('Dane wejściowe'!B6*('Dane wejściowe'!B22*(1-('Dane wejściowe'!B7/100))+'Dane wejściowe'!B23*('Dane wejściowe'!B7/100))*(1+(('Dane wejściowe'!B8/200000)-1)*'Dane wejściowe'!B24)*(1+'Dane wejściowe'!B19/100))*'Dane wejściowe'!B5*'Dane wejściowe'!B9 | D21: Porównaj który tańszy dla reklamodawcy

Sheet Scenariusze
A1: AdRide — Scenariusze: Wpływ liczby aut (zysk operacyjny, bez kosztu prawnego)
A2: Aut | B2: Rev SUB/mc | C2: Zysk SUB | D2: M%SUB | E2: BEP SUB | G2: Zysk ABO | H2: M%ABO | I2: BEP ABO | J2: Δ SUB−ABO | K2: Lepszy?
A3: 1 | B3: =('Dane wejściowe'!B6*('Dane wejściowe'!B22*(1-('Dane wejściowe'!B7/100))+'Dane wejściowe'!B23*('Dane wejściowe'!B7/100))*(1+(('Dane wejściowe'!B8/200000)-1)*'Dane wejściowe'!B24))*1 | C3: =(('Dane wejściowe'!B6*('Dane wejściowe'!B22*(1-('Dane wejściowe'!B7/100))+'Dane wejściowe'!B23*('Dane wejściowe'!B7/100))*(1+(('Dane wejściowe'!B8/200000)-1)*'Dane wejściowe'!B24))*1)-(('Dane wejściowe'!B6*('Dane wejściowe'!B12*(1-('Dane wejściowe'!B7/100))+'Dane wejściowe'!B13*('Dane wejściowe'!B7/100))*(1+(('Dane wejściowe'!B8/200000)-1)*'Dane wejściowe'!B24)*'Dane wejściowe'!B14)*1)-'Dane wejściowe'!B29 | D3: =IFERROR(((('Dane wejściowe'!B6*('Dane wejściowe'!B22*(1-('Dane wejściowe'!B7/100))+'Dane wejściowe'!B23*('Dane wejściowe'!B7/100))*(1+(('Dane wejściowe'!B8/200000)-1)*'Dane wejściowe'!B24))*1)-(('Dane wejściowe'!B6*('Dane wejściowe'!B12*(1-('Dane wejściowe'!B7/100))+'Dane wejściowe'!B13*('Dane wejściowe'!B7/100))*(1+(('Dane wejściowe'!B8/200000)-1)*'Dane wejściowe'!B24)*'Dane wejściowe'!B14)*1)-'Dane wejściowe'!B29)/(('Dane wejściowe'!B6*('Dane wejściowe'!B22*(1-('Dane wejściowe'!B7/100))+'Dane wejściowe'!B23*('Dane wejściowe'!B7/100))*(1+(('Dane wejściowe'!B8/200000)-1)*'Dane wejściowe'!B24))*1)*100,0) | E3: =IFERROR(IF(((('Dane wejściowe'!B6*('Dane wejściowe'!B22*(1-('Dane wejściowe'!B7/100))+'Dane wejściowe'!B23*('Dane wejściowe'!B7/100))*(1+(('Dane wejściowe'!B8/200000)-1)*'Dane wejściowe'!B24))*1)-(('Dane wejściowe'!B6*('Dane wejściowe'!B12*(1-('Dane wejściowe'!B7/100))+'Dane wejściowe'!B13*('Dane wejściowe'!B7/100))*(1+(('Dane wejściowe'!B8/200000)-1)*'Dane wejściowe'!B24)*'Dane wejściowe'!B14)*1)-'Dane wejściowe'!B29)>0,'Dane wejściowe'!B28/((('Dane wejściowe'!B6*('Dane wejściowe'!B22*(1-('Dane wejściowe'!B7/100))+'Dane wejściowe'!B23*('Dane wejściowe'!B7/100))*(1+(('Dane wejściowe'!B8/200000)-1)*'Dane wejściowe'!B24))*1)-(('Dane wejściowe'!B6*('Dane wejściowe'!B12*(1-('Dane wejściowe'!B7/100))+'Dane wejściowe'!B13*('Dane wejściowe'!B7/100))*(1+(('Dane wejściowe'!B8/200000)-1)*'Dane wejściowe'!B24)*'Dane wejściowe'!B14)*1)-'Dane wejściowe'!B29),"N/A"),"N/A") | G3: =(('Dane wejściowe'!B6*('Dane wejściowe'!B22*(1-('Dane wejściowe'!B7/100))+'Dane wejściowe'!B23*('Dane wejściowe'!B7/100))*(1+(('Dane wejściowe'!B8/200000)-1)*'Dane wejściowe'!B24)*(1+'Dane wejściowe'!B19/100))*1)-(('Dane wejściowe'!B6*('Dane wejściowe'!B12*(1-('Dane wejściowe'!B7/100))+'Dane wejściowe'!B13*('Dane wejściowe'!B7/100))*(1+(('Dane wejściowe'!B8/200000)-1)*'Dane wejściowe'!B24)*'Dane wejściowe'!B14+'Dane wejściowe'!B17/MAX('Dane wejściowe'!B9,12)+'Dane wejściowe'!B18/MAX('Dane wejściowe'!B9,12))*1)-'Dane wejściowe'!B29 | H3: =IFERROR(((('Dane wejściowe'!B6*('Dane wejściowe'!B22*(1-('Dane wejściowe'!B7/100))+'Dane wejściowe'!B23*('Dane wejściowe'!B7/100))*(1+(('Dane wejściowe'!B8/200000)-1)*'Dane wejściowe'!B24)*(1+'Dane wejściowe'!B19/100))*1)-(('Dane wejściowe'!B6*('Dane wejściowe'!B12*(1-('Dane wejściowe'!B7/100))+'Dane wejściowe'!B13*('Dane wejściowe'!B7/100))*(1+(('Dane wejściowe'!B8/200000)-1)*'Dane wejściowe'!B24)*'Dane wejściowe'!B14+'Dane wejściowe'!B17/MAX('Dane wejściowe'!B9,12)+'Dane wejściowe'!B18/MAX('Dane wejściowe'!B9,12))*1)-'Dane wejściowe'!B29)/(('Dane wejściowe'!B6*('Dane wejściowe'!B22*(1-('Dane wejściowe'!B7/100))+'Dane wejściowe'!B23*('Dane wejściowe'!B7/100))*(1+(('Dane wejściowe'!B8/200000)-1)*'Dane wejściowe'!B24)*(1+'Dane wejściowe'!B19/100))*1)*100,0) | I3: =IFERROR(IF(((('Dane wejściowe'!B6*('Dane wejściowe'!B22*(1-('Dane wejściowe'!B7/100))+'Dane wejściowe'!B23*('Dane wejściowe'!B7/100))*(1+(('Dane wejściowe'!B8/200000)-1)*'Dane wejściowe'!B24)*(1+'Dane wejściowe'!B19/100))*1)-(('Dane wejściowe'!B6*('Dane wejściowe'!B12*(1-('Dane wejściowe'!B7/100))+'Dane wejściowe'!B13*('Dane wejściowe'!B7/100))*(1+(('Dane wejściowe'!B8/200000)-1)*'Dane wejściowe'!B24)*'Dane wejściowe'!B14+'Dane wejściowe'!B17/MAX('Dane wejściowe'!B9,12)+'Dane wejściowe'!B18/MAX('Dane wejściowe'!B9,12))*1)-'Dane wejściowe'!B29)>0,'Dane wejściowe'!B28/((('Dane wejściowe'!B6*('Dane wejściowe'!B22*(1-('Dane wejściowe'!B7/100))+'Dane wejściowe'!B23*('Dane wejściowe'!B7/100))*(1+(('Dane wejściowe'!B8/200000)-1)*'Dane wejściowe'!B24)*(1+'Dane wejściowe'!B19/100))*1)-(('Dane wejściowe'!B6*('Dane wejściowe'!B12*(1-('Dane wejściowe'!B7/100))+'Dane wejściowe'!B13*('Dane wejściowe'!B7/100))*(1+(('Dane wejściowe'!B8/200000)-1)*'Dane wejściowe'!B24)*'Dane wejściowe'!B14+'Dane wejściowe'!B17/MAX('Dane wejściowe'!B9,12)+'Dane wejściowe'!B18/MAX('Dane wejściowe'!B9,12))*1)-'Dane wejściowe'!B29),"N/A"),"N/A") | J3: =((('Dane wejściowe'!B6*('Dane wejściowe'!B22*(1-('Dane wejściowe'!B7/100))+'Dane wejściowe'!B23*('Dane wejściowe'!B7/100))*(1+(('Dane wejściowe'!B8/200000)-1)*'Dane wejściowe'!B24))*1)-(('Dane wejściowe'!B6*('Dane wejściowe'!B12*(1-('Dane wejściowe'!B7/100))+'Dane wejściowe'!B13*('Dane wejściowe'!B7/100))*(1+(('Dane wejściowe'!B8/200000)-1)*'Dane wejściowe'!B24)*'Dane wejściowe'!B14)*1)-'Dane wejściowe'!B29)-((('Dane wejściowe'!B6*('Dane wejściowe'!B22*(1-('Dane wejściowe'!B7/100))+'Dane wejściowe'!B23*('Dane wejściowe'!B7/100))*(1+(('Dane wejściowe'!B8/200000)-1)*'Dane wejściowe'!B24)*(1+'Dane wejściowe'!B19/100))*1)-(('Dane wejściowe'!B6*('Dane wejściowe'!B12*(1-('Dane wejściowe'!B7/100))+'Dane wejściowe'!B13*('Dane wejściowe'!B7/100))*(1+(('Dane wejściowe'!B8/200000)-1)*'Dane wejściowe'!B24)*'Dane wejściowe'!B14+'Dane wejściowe'!B17/MAX('Dane wejściowe'!B9,12)+'Dane wejściowe'!B18/MAX('Dane wejściowe'!B9,12))*1)-'Dane wejściowe'!B29) | K3: =IF(((('Dane wejściowe'!B6*('Dane wejściowe'!B22*(1-('Dane wejściowe'!B7/100))+'Dane wejściowe'!B23*('Dane wejściowe'!B7/100))*(1+(('Dane wejściowe'!B8/200000)-1)*'Dane wejściowe'!B24))*1)-(('Dane wejściowe'!B6*('Dane wejściowe'!B12*(1-('Dane wejściowe'!B7/100))+'Dane wejściowe'!B13*('Dane wejściowe'!B7/100))*(1+(('Dane wejściowe'!B8/200000)-1)*'Dane wejściowe'!B24)*'Dane wejściowe'!B14)*1)-'Dane wejściowe'!B29)>((('Dane wejściowe'!B6*('Dane wejściowe'!B22*(1-('Dane wejściowe'!B7/100))+'Dane wejściowe'!B23*('Dane wejściowe'!B7/100))*(1+(('Dane wejściowe'!B8/200000)-1)*'Dane wejściowe'!B24)*(1+'Dane wejściowe'!B19/100))*1)-(('Dane wejściowe'!B6*('Dane wejściowe'!B12*(1-('Dane wejściowe'!B7/100))+'Dane wejściowe'!B13*('Dane wejściowe'!B7/100))*(1+(('Dane wejściowe'!B8/200000)-1)*'Dane wejściowe'!B24)*'Dane wejściowe'!B14+'Dane wejściowe'!B17/MAX('Dane wejściowe'!B9,12)+'Dane wejściowe'!B18/MAX('Dane wejściowe'!B9,12))*1)-'Dane wejściowe'!B29),"SUB","ABO")
A4: 3 | B4: =('Dane wejściowe'!B6*('Dane wejściowe'!B22*(1-('Dane wejściowe'!B7/100))+'Dane wejściowe'!B23*('Dane wejściowe'!B7/100))*(1+(('Dane wejściowe'!B8/200000)-1)*'Dane wejściowe'!B24))*3 | C4: =(('Dane wejściowe'!B6*('Dane wejściowe'!B22*(1-('Dane wejściowe'!B7/100))+'Dane wejściowe'!B23*('Dane wejściowe'!B7/100))*(1+(('Dane wejściowe'!B8/200000)-1)*'Dane wejściowe'!B24))*3)-(('Dane wejściowe'!B6*('Dane wejściowe'!B12*(1-('Dane wejściowe'!B7/100))+'Dane wejściowe'!B13*('Dane wejściowe'!B7/100))*(1+(('Dane wejściowe'!B8/200000)-1)*'Dane wejściowe'!B24)*'Dane wejściowe'!B14)*3)-'Dane wejściowe'!B29 | D4: =IFERROR(((('Dane wejściowe'!B6*('Dane wejściowe'!B22*(1-('Dane wejściowe'!B7/100))+'Dane wejściowe'!B23*('Dane wejściowe'!B7/100))*(1+(('Dane wejściowe'!B8/200000)-1)*'Dane wejściowe'!B24))*3)-(('Dane wejściowe'!B6*('Dane wejściowe'!B12*(1-('Dane wejściowe'!B7/100))+'Dane wejściowe'!B13*('Dane wejściowe'!B7/100))*(1+(('Dane wejściowe'!B8/200000)-1)*'Dane wejściowe'!B24)*'Dane wejściowe'!B14)*3)-'Dane wejściowe'!B29)/(('Dane wejściowe'!B6*('Dane wejściowe'!B22*(1-('Dane wejściowe'!B7/100))+'Dane wejściowe'!B23*('Dane wejściowe'!B7/100))*(1+(('Dane wejściowe'!B8/200000)-1)*'Dane wejściowe'!B24))*3)*100,0) | E4: =IFERROR(IF(((('Dane wejściowe'!B6*('Dane wejściowe'!B22*(1-('Dane wejściowe'!B7/100))+'Dane wejściowe'!B23*('Dane wejściowe'!B7/100))*(1+(('Dane wejściowe'!B8/200000)-1)*'Dane wejściowe'!B24))*3)-(('Dane wejściowe'!B6*('Dane wejściowe'!B12*(1-('Dane wejściowe'!B7/100))+'Dane wejściowe'!B13*('Dane wejściowe'!B7/100))*(1+(('Dane wejściowe'!B8/200000)-1)*'Dane wejściowe'!B24)*'Dane wejściowe'!B14)*3)-'Dane wejściowe'!B29)>0,'Dane wejściowe'!B28/((('Dane wejściowe'!B6*('Dane wejściowe'!B22*(1-('Dane wejściowe'!B7/100))+'Dane wejściowe'!B23*('Dane wejściowe'!B7/100))*(1+(('Dane wejściowe'!B8/200000)-1)*'Dane wejściowe'!B24))*3)-(('Dane wejściowe'!B6*('Dane wejściowe'!B12*(1-('Dane wejściowe'!B7/100))+'Dane wejściowe'!B13*('Dane wejściowe'!B7/100))*(1+(('Dane wejściowe'!B8/200000)-1)*'Dane wejściowe'!B24)*'Dane wejściowe'!B14)*3)-'Dane wejściowe'!B29),"N/A"),"N/A") | G4: =(('Dane wejściowe'!B6*('Dane wejściowe'!B22*(1-('Dane wejściowe'!B7/100))+'Dane wejściowe'!B23*('Dane wejściowe'!B7/100))*(1+(('Dane wejściowe'!B8/200000)-1)*'Dane wejściowe'!B24)*(1+'Dane wejściowe'!B19/100))*3)-(('Dane wejściowe'!B6*('Dane wejściowe'!B12*(1-('Dane wejściowe'!B7/100))+'Dane wejściowe'!B13*('Dane wejściowe'!B7/100))*(1+(('Dane wejściowe'!B8/200000)-1)*'Dane wejściowe'!B24)*'Dane wejściowe'!B14+'Dane wejściowe'!B17/MAX('Dane wejściowe'!B9,12)+'Dane wejściowe'!B18/MAX('Dane wejściowe'!B9,12))*3)-'Dane wejściowe'!B29 | H4: =IFERROR(((('Dane wejściowe'!B6*('Dane wejściowe'!B22*(1-('Dane wejściowe'!B7/100))+'Dane wejściowe'!B23*('Dane wejściowe'!B7/100))*(1+(('Dane wejściowe'!B8/200000)-1)*'Dane wejściowe'!B24)*(1+'Dane wejściowe'!B19/100))*3)-(('Dane wejściowe'!B6*('Dane wejściowe'!B12*(1-('Dane wejściowe'!B7/100))+'Dane wejściowe'!B13*('Dane wejściowe'!B7/100))*(1+(('Dane wejściowe'!B8/200000)-1)*'Dane wejściowe'!B24)*'Dane wejściowe'!B14+'Dane wejściowe'!B17/MAX('Dane wejściowe'!B9,12)+'Dane wejściowe'!B18/MAX('Dane wejściowe'!B9,12))*3)-'Dane wejściowe'!B29)/(('Dane wejściowe'!B6*('Dane wejściowe'!B22*(1-('Dane wejściowe'!B7/100))+'Dane wejściowe'!B23*('Dane wejściowe'!B7/100))*(1+(('Dane wejściowe'!B8/200000)-1)*'Dane wejściowe'!B24)*(1+'Dane wejściowe'!B19/100))*3)*100,0) | I4: =IFERROR(IF(((('Dane wejściowe'!B6*('Dane wejściowe'!B22*(1-('Dane wejściowe'!B7/100))+'Dane wejściowe'!B23*('Dane wejściowe'!B7/100))*(1+(('Dane wejściowe'!B8/200000)-1)*'Dane wejściowe'!B24)*(1+'Dane wejściowe'!B19/100))*3)-(('Dane wejściowe'!B6*('Dane wejściowe'!B12*(1-('Dane wejściowe'!B7/100))+'Dane wejściowe'!B13*('Dane wejściowe'!B7/100))*(1+(('Dane wejściowe'!B8/200000)-1)*'Dane wejściowe'!B24)*'Dane wejściowe'!B14+'Dane wejściowe'!B17/MAX('Dane wejściowe'!B9,12)+'Dane wejściowe'!B18/MAX('Dane wejściowe'!B9,12))*3)-'Dane wejściowe'!B29)>0,'Dane wejściowe'!B28/((('Dane wejściowe'!B6*('Dane wejściowe'!B22*(1-('Dane wejściowe'!B7/100))+'Dane wejściowe'!B23*('Dane wejściowe'!B7/100))*(1+(('Dane wejściowe'!B8/200000)-1)*'Dane wejściowe'!B24)*(1+'Dane wejściowe'!B19/100))*3)-(('Dane wejściowe'!B6*('Dane wejściowe'!B12*(1-('Dane wejściowe'!B7/100))+'Dane wejściowe'!B13*('Dane wejściowe'!B7/100))*(1+(('Dane wejściowe'!B8/200000)-1)*'Dane wejściowe'!B24)*'Dane wejściowe'!B14+'Dane wejściowe'!B17/MAX('Dane wejściowe'!B9,12)+'Dane wejściowe'!B18/MAX('Dane wejściowe'!B9,12))*3)-'Dane wejściowe'!B29),"N/A"),"N/A") | J4: =((('Dane wejściowe'!B6*('Dane wejściowe'!B22*(1-('Dane wejściowe'!B7/100))+'Dane wejściowe'!B23*('Dane wejściowe'!B7/100))*(1+(('Dane wejściowe'!B8/200000)-1)*'Dane wejściowe'!B24))*3)-(('Dane wejściowe'!B6*('Dane wejściowe'!B12*(1-('Dane wejściowe'!B7/100))+'Dane wejściowe'!B13*('Dane wejściowe'!B7/100))*(1+(('Dane wejściowe'!B8/200000)-1)*'Dane wejściowe'!B24)*'Dane wejściowe'!B14)*3)-'Dane wejściowe'!B29)-((('Dane wejściowe'!B6*('Dane wejściowe'!B22*(1-('Dane wejściowe'!B7/100))+'Dane wejściowe'!B23*('Dane wejściowe'!B7/100))*(1+(('Dane wejściowe'!B8/200000)-1)*'Dane wejściowe'!B24)*(1+'Dane wejściowe'!B19/100))*3)-(('Dane wejściowe'!B6*('Dane wejściowe'!B12*(1-('Dane wejściowe'!B7/100))+'Dane wejściowe'!B13*('Dane wejściowe'!B7/100))*(1+(('Dane wejściowe'!B8/200000)-1)*'Dane wejściowe'!B24)*'Dane wejściowe'!B14+'Dane wejściowe'!B17/MAX('Dane wejściowe'!B9,12)+'Dane wejściowe'!B18/MAX('Dane wejściowe'!B9,12))*3)-'Dane wejściowe'!B29) | K4: =IF(((('Dane wejściowe'!B6*('Dane wejściowe'!B22*(1-('Dane wejściowe'!B7/100))+'Dane wejściowe'!B23*('Dane wejściowe'!B7/100))*(1+(('Dane wejściowe'!B8/200000)-1)*'Dane wejściowe'!B24))*3)-(('Dane wejściowe'!B6*('Dane wejściowe'!B12*(1-('Dane wejściowe'!B7/100))+'Dane wejściowe'!B13*('Dane wejściowe'!B7/100))*(1+(('Dane wejściowe'!B8/200000)-1)*'Dane wejściowe'!B24)*'Dane wejściowe'!B14)*3)-'Dane wejściowe'!B29)>((('Dane wejściowe'!B6*('Dane wejściowe'!B22*(1-('Dane wejściowe'!B7/100))+'Dane wejściowe'!B23*('Dane wejściowe'!B7/100))*(1+(('Dane wejściowe'!B8/200000)-1)*'Dane wejściowe'!B24)*(1+'Dane wejściowe'!B19/100))*3)-(('Dane wejściowe'!B6*('Dane wejściowe'!B12*(1-('Dane wejściowe'!B7/100))+'Dane wejściowe'!B13*('Dane wejściowe'!B7/100))*(1+(('Dane wejściowe'!B8/200000)-1)*'Dane wejściowe'!B24)*'Dane wejściowe'!B14+'Dane wejściowe'!B17/MAX('Dane wejściowe'!B9,12)+'Dane wejściowe'!B18/MAX('Dane wejściowe'!B9,12))*3)-'Dane wejściowe'!B29),"SUB","ABO")
A5: 5 | B5: =('Dane wejściowe'!B6*('Dane wejściowe'!B22*(1-('Dane wejściowe'!B7/100))+'Dane wejściowe'!B23*('Dane wejściowe'!B7/100))*(1+(('Dane wejściowe'!B8/200000)-1)*'Dane wejściowe'!B24))*5 | C5: =(('Dane wejściowe'!B6*('Dane wejściowe'!B22*(1-('Dane wejściowe'!B7/100))+'Dane wejściowe'!B23*('Dane wejściowe'!B7/100))*(1+(('Dane wejściowe'!B8/200000)-1)*'Dane wejściowe'!B24))*5)-(('Dane wejściowe'!B6*('Dane wejściowe'!B12*(1-('Dane wejściowe'!B7/100))+'Dane wejściowe'!B13*('Dane wejściowe'!B7/100))*(1+(('Dane wejściowe'!B8/200000)-1)*'Dane wejściowe'!B24)*'Dane wejściowe'!B14)*5)-'Dane wejściowe'!B29 | D5: =IFERROR(((('Dane wejściowe'!B6*('Dane wejściowe'!B22*(1-('Dane wejściowe'!B7/100))+'Dane wejściowe'!B23*('Dane wejściowe'!B7/100))*(1+(('Dane wejściowe'!B8/200000)-1)*'Dane wejściowe'!B24))*5)-(('Dane wejściowe'!B6*('Dane wejściowe'!B12*(1-('Dane wejściowe'!B7/100))+'Dane wejściowe'!B13*('Dane wejściowe'!B7/100))*(1+(('Dane wejściowe'!B8/200000)-1)*'Dane wejściowe'!B24)*'Dane wejściowe'!B14)*5)-'Dane wejściowe'!B29)/(('Dane wejściowe'!B6*('Dane wejściowe'!B22*(1-('Dane wejściowe'!B7/100))+'Dane wejściowe'!B23*('Dane wejściowe'!B7/100))*(1+(('Dane wejściowe'!B8/200000)-1)*'Dane wejściowe'!B24))*5)*100,0) | E5: =IFERROR(IF(((('Dane wejściowe'!B6*('Dane wejściowe'!B22*(1-('Dane wejściowe'!B7/100))+'Dane wejściowe'!B23*('Dane wejściowe'!B7/100))*(1+(('Dane wejściowe'!B8/200000)-1)*'Dane wejściowe'!B24))*5)-(('Dane wejściowe'!B6*('Dane wejściowe'!B12*(1-('Dane wejściowe'!B7/100))+'Dane wejściowe'!B13*('Dane wejściowe'!B7/100))*(1+(('Dane wejściowe'!B8/200000)-1)*'Dane wejściowe'!B24)*'Dane wejściowe'!B14)*5)-'Dane wejściowe'!B29)>0,'Dane wejściowe'!B28/((('Dane wejściowe'!B6*('Dane wejściowe'!B22*(1-('Dane wejściowe'!B7/100))+'Dane wejściowe'!B23*('Dane wejściowe'!B7/100))*(1+(('Dane wejściowe'!B8/200000)-1)*'Dane wejściowe'!B24))*5)-(('Dane wejściowe'!B6*('Dane wejściowe'!B12*(1-('Dane wejściowe'!B7/100))+'Dane wejściowe'!B13*('Dane wejściowe'!B7/100))*(1+(('Dane wejściowe'!B8/200000)-1)*'Dane wejściowe'!B24)*'Dane wejściowe'!B14)*5)-'Dane wejściowe'!B29),"N/A"),"N/A") | G5: =(('Dane wejściowe'!B6*('Dane wejściowe'!B22*(1-('Dane wejściowe'!B7/100))+'Dane wejściowe'!B23*('Dane wejściowe'!B7/100))*(1+(('Dane wejściowe'!B8/200000)-1)*'Dane wejściowe'!B24)*(1+'Dane wejściowe'!B19/100))*5)-(('Dane wejściowe'!B6*('Dane wejściowe'!B12*(1-('Dane wejściowe'!B7/100))+'Dane wejściowe'!B13*('Dane wejściowe'!B7/100))*(1+(('Dane wejściowe'!B8/200000)-1)*'Dane wejściowe'!B24)*'Dane wejściowe'!B14+'Dane wejściowe'!B17/MAX('Dane wejściowe'!B9,12)+'Dane wejściowe'!B18/MAX('Dane wejściowe'!B9,12))*5)-'Dane wejściowe'!B29 | H5: =IFERROR(((('Dane wejściowe'!B6*('Dane wejściowe'!B22*(1-('Dane wejściowe'!B7/100))+'Dane wejściowe'!B23*('Dane wejściowe'!B7/100))*(1+(('Dane wejściowe'!B8/200000)-1)*'Dane wejściowe'!B24)*(1+'Dane wejściowe'!B19/100))*5)-(('Dane wejściowe'!B6*('Dane wejściowe'!B12*(1-('Dane wejściowe'!B7/100))+'Dane wejściowe'!B13*('Dane wejściowe'!B7/100))*(1+(('Dane wejściowe'!B8/200000)-1)*'Dane wejściowe'!B24)*'Dane wejściowe'!B14+'Dane wejściowe'!B17/MAX('Dane wejściowe'!B9,12)+'Dane wejściowe'!B18/MAX('Dane wejściowe'!B9,12))*5)-'Dane wejściowe'!B29)/(('Dane wejściowe'!B6*('Dane wejściowe'!B22*(1-('Dane wejściowe'!B7/100))+'Dane wejściowe'!B23*('Dane wejściowe'!B7/100))*(1+(('Dane wejściowe'!B8/200000)-1)*'Dane wejściowe'!B24)*(1+'Dane wejściowe'!B19/100))*5)*100,0) | I5: =IFERROR(IF(((('Dane wejściowe'!B6*('Dane wejściowe'!B22*(1-('Dane wejściowe'!B7/100))+'Dane wejściowe'!B23*('Dane wejściowe'!B7/100))*(1+(('Dane wejściowe'!B8/200000)-1)*'Dane wejściowe'!B24)*(1+'Dane wejściowe'!B19/100))*5)-(('Dane wejściowe'!B6*('Dane wejściowe'!B12*(1-('Dane wejściowe'!B7/100))+'Dane wejściowe'!B13*('Dane wejściowe'!B7/100))*(1+(('Dane wejściowe'!B8/200000)-1)*'Dane wejściowe'!B24)*'Dane wejściowe'!B14+'Dane wejściowe'!B17/MAX('Dane wejściowe'!B9,12)+'Dane wejściowe'!B18/MAX('Dane wejściowe'!B9,12))*5)-'Dane wejściowe'!B29)>0,'Dane wejściowe'!B28/((('Dane wejściowe'!B6*('Dane wejściowe'!B22*(1-('Dane wejściowe'!B7/100))+'Dane wejściowe'!B23*('Dane wejściowe'!B7/100))*(1+(('Dane wejściowe'!B8/200000)-1)*'Dane wejściowe'!B24)*(1+'Dane wejściowe'!B19/100))*5)-(('Dane wejściowe'!B6*('Dane wejściowe'!B12*(1-('Dane wejściowe'!B7/100))+'Dane wejściowe'!B13*('Dane wejściowe'!B7/100))*(1+(('Dane wejściowe'!B8/200000)-1)*'Dane wejściowe'!B24)*'Dane wejściowe'!B14+'Dane wejściowe'!B17/MAX('Dane wejściowe'!B9,12)+'Dane wejściowe'!B18/MAX('Dane wejściowe'!B9,12))*5)-'Dane wejściowe'!B29),"N/A"),"N/A") | J5: =((('Dane wejściowe'!B6*('Dane wejściowe'!B22*(1-('Dane wejściowe'!B7/100))+'Dane wejściowe'!B23*('Dane wejściowe'!B7/100))*(1+(('Dane wejściowe'!B8/200000)-1)*'Dane wejściowe'!B24))*5)-(('Dane wejściowe'!B6*('Dane wejściowe'!B12*(1-('Dane wejściowe'!B7/100))+'Dane wejściowe'!B13*('Dane wejściowe'!B7/100))*(1+(('Dane wejściowe'!B8/200000)-1)*'Dane wejściowe'!B24)*'Dane wejściowe'!B14)*5)-'Dane wejściowe'!B29)-((('Dane wejściowe'!B6*('Dane wejściowe'!B22*(1-('Dane wejściowe'!B7/100))+'Dane wejściowe'!B23*('Dane wejściowe'!B7/100))*(1+(('Dane wejściowe'!B8/200000)-1)*'Dane wejściowe'!B24)*(1+'Dane wejściowe'!B19/100))*5)-(('Dane wejściowe'!B6*('Dane wejściowe'!B12*(1-('Dane wejściowe'!B7/100))+'Dane wejściowe'!B13*('Dane wejściowe'!B7/100))*(1+(('Dane wejściowe'!B8/200000)-1)*'Dane wejściowe'!B24)*'Dane wejściowe'!B14+'Dane wejściowe'!B17/MAX('Dane wejściowe'!B9,12)+'Dane wejściowe'!B18/MAX('Dane wejściowe'!B9,12))*5)-'Dane wejściowe'!B29) | K5: =IF(((('Dane wejściowe'!B6*('Dane wejściowe'!B22*(1-('Dane wejściowe'!B7/100))+'Dane wejściowe'!B23*('Dane wejściowe'!B7/100))*(1+(('Dane wejściowe'!B8/200000)-1)*'Dane wejściowe'!B24))*5)-(('Dane wejściowe'!B6*('Dane wejściowe'!B12*(1-('Dane wejściowe'!B7/100))+'Dane wejściowe'!B13*('Dane wejściowe'!B7/100))*(1+(('Dane wejściowe'!B8/200000)-1)*'Dane wejściowe'!B24)*'Dane wejściowe'!B14)*5)-'Dane wejściowe'!B29)>((('Dane wejściowe'!B6*('Dane wejściowe'!B22*(1-('Dane wejściowe'!B7/100))+'Dane wejściowe'!B23*('Dane wejściowe'!B7/100))*(1+(('Dane wejściowe'!B8/200000)-1)*'Dane wejściowe'!B24)*(1+'Dane wejściowe'!B19/100))*5)-(('Dane wejściowe'!B6*('Dane wejściowe'!B12*(1-('Dane wejściowe'!B7/100))+'Dane wejściowe'!B13*('Dane wejściowe'!B7/100))*(1+(('Dane wejściowe'!B8/200000)-1)*'Dane wejściowe'!B24)*'Dane wejściowe'!B14+'Dane wejściowe'!B17/MAX('Dane wejściowe'!B9,12)+'Dane wejściowe'!B18/MAX('Dane wejściowe'!B9,12))*5)-'Dane wejściowe'!B29),"SUB","ABO")
